Workbook
Name _1.: 'EVALUASI KINERJA KUANTI JF'!$R$47
Name _1.: 'EVALUASI KINERJA KUANTI JF (2)'!$R$47
Name Absensi: #REF!
Name Absensi: #REF!
Name Absensi: #REF!
Name Absensi: #REF!
Name Absensi: #REF!
Name Absensi: #REF!
Name Absensi: #REF!
Name Absensi: #REF!
Name AK: [1]Target!$AX$7:$BF$143
Name Akhir: [2]Sheet12!$B$5:$K$11
Name analisis: #REF!
Name analisis: #REF!
Name analisis: #REF!
Name analisis: #REF!
Name analisis: #REF!
Name analisis: #REF!
Name analisis: #REF!
Name analisis: #REF!
Name angka_kredit: [1]Target!$AX$7:$BF$143
Name bilat: [1]AngkaKredit!$C$83:$H$95
Name bind: #REF!
Name bind: #REF!
Name bind: #REF!
Name bind: #REF!
Name bind: #REF!
Name bind: #REF!
Name bind: #REF!
Name bind: #REF!
Name bing: #REF!
Name bing: #REF!
Name bing: #REF!
Name bing: #REF!
Name bing: #REF!
Name bing: #REF!
Name bing: #REF!
Name bing: #REF!
Name BUDIDAYA: #REF!
Name BUDIDAYA: #REF!
Name BUDIDAYA: #REF!
Name BUDIDAYA: #REF!
Name BUDIDAYA: #REF!
Name BUDIDAYA: #REF!
Name BUDIDAYA: #REF!
Name BUDIDAYA: #REF!
Name butir1bk: '[3]AK BK'!$G$7:$I$18
Name butir1gk: '[3]AK BK'!$G$119:$I$130
Name butir2bk: '[3]AK BK'!$G$19:$I$30
Name butir2gk: '[3]AK BK'!$G$131:$I$142
Name butir3bk: '[3]AK BK'!$G$31:$I$42
Name butir3gk: '[3]AK BK'!$G$143:$I$154
Name butir4bk: '[3]AK BK'!$G$43:$I$54
Name butir4gk: '[3]AK BK'!$G$155:$I$166
Name butir5bk: '[3]AK BK'!$G$55:$I$66
Name butir5gk: '[3]AK BK'!$G$167:$I$178
Name butir6gk: '[3]AK BK'!$G$179:$I$190
Name butir7bk: '[3]AK BK'!$G$79:$I$90
Name butir7gk: '[3]AK BK'!$G$191:$I$202
Name butir8bk: '[3]AK BK'!$G$91:$I$102

Sheet COVER
L1: DATA | M1: A
C16: PENILAIAN KINERJA
C17: PEGAWAI APARATUR SIPIL NEGARA
C18: SESUAI PERMENEGPAN RB. 06 TAHUN 2022
C24: JANGKA WAKTU PENILAIAN
C25: ='DOK. EVALUASI KINERJA PEGAWAI'!D15&"" -> 01 JANUARI 2022 S.D 31 DESEMBER 2022
C32: NAMA | D32: : | E32: ='SKP JF (KUANTITATIF)'!D8&"" -> RUSLAN, S.Pd
C33: NIP | D33: : | E33: ='SKP JF (KUANTITATIF)'!D9&"" -> 19660625 199112 1 001
C34: PANGKAT /GOL | D34: : | E34: ='SKP JF (KUANTITATIF)'!D10&"" -> PEMBINA TK.I/ IV.b
C35: JABATAN | D35: : | E35: ='SKP JF (KUANTITATIF)'!D11&"" -> KEPALA SEKOLAH
C36: UNIT KERJA | D36: : | E36: ='SKP JF (KUANTITATIF)'!D12&"" -> UPTD SDN 1 KOTABUMI TENGAH KAB. LAMPUNG UTARA
C44: =IF(M1="A","PEMERINTAH "&'00 DATA'!D25&" "&'00 DATA'!F25&"",IF(M1="B","KEMENAG "&'00 DATA'!D25&" "&'00 DATA'!F25&"")) -> PEMERINTAH KAB. LAMPUNG UTARA
C45: ='00 DATA'!P4&" "&'00 DATA'!P5&"" -> TAHUN 2022

Sheet SKP JF (KUANTITATIF)
L1: HOME
B2: SASARAN KINERJA PEGAWAI
B3: ="JABATAN FUNGSIONAL "&'00 DATA'!F1&"" -> JABATAN FUNGSIONAL KEPALA SEKOLAH
B4: PENDEKATAN HASIL KERJA KUANTITATIF
B6: ='00 DATA'!F24&" "&'00 DATA'!D25&" "&'00 DATA'!F25&"" -> DINAS PENDIDIKAN KAB. LAMPUNG UTARA | F6: PERIODE PENILAIAN: | H6: ='00 DATA'!N6&" S.D "&'00 DATA'!N7&"" -> 01 JANUARI 2022 S.D 31 DESEMBER 2022
B7: NO | C7: PEGAWAI YANG DINILAI | F7: NO | G7: PEJABAT PENILAI KINERJA
B8: 1 | C8: NAMA | D8: ='00 DATA'!F5&"" -> RUSLAN, S.Pd | F8: 1 | G8: NAMA | I8: ='00 DATA'!F12&"" -> TUTI ROSPASARI, S.Pd. M.Pd.
B9: 2 | C9: NIP | D9: ='00 DATA'!F6&"" -> 19660625 199112 1 001 | F9: 2 | G9: NIP | I9: ='00 DATA'!F13&"" -> 19721025 199802 2 003
B10: 3 | C10: PANGKAT/GOL. RUANG | D10: ='00 DATA'!F7&"/ "&'00 DATA'!G7&" "&'00 DATA'!H7&"" -> PEMBINA TK.I/ IV.b | F10: 3 | G10: PANGKAT/GOL. RUANG | I10: ='00 DATA'!F14&"" -> PEMBINA TK.I (IV/b)
B11: 4 | C11: JABATAN | D11: ='00 DATA'!F8&"" -> KEPALA SEKOLAH | F11: 4 | G11: JABATAN | I11: ='00 DATA'!F15&"" -> SEKRETARIS DINAS | N11: KODE ATSN | O11: KODE IKU
B12: 5 | C12: UNIT KERJA | D12: ='00 DATA'!F9&" "&'00 DATA'!D10&" "&'00 DATA'!F10&"" -> UPTD SDN 1 KOTABUMI TENGAH KAB. LAMPUNG UTARA | F12: 5 | G12: UNIT KERJA | I12: ='00 DATA'!F16&" "&'00 DATA'!D17&" "&'00 DATA'!F17&"" -> DINAS PENDIDIKAN KAB. LAMPUNG UTARA | N12: D=1; CD=2, KS=4 | O12: P=3; KS=4, GR=5
B13: HASIL KERJA
B14: NO. | C14: RENCANA HASIL KERJA ATASAN YANG DIINTERVENSI | D14: RENCANA HASIL KERJA | G14: ASPEK | H14: INDIKATOR KINERJA INDIVIDU | K14: TARGET | N14: DIISI BRDSARKN MATRIK PERAN HASIL / TUPOK
B15: (1) | C15: (2) | D15: (3) | G15: (4) | H15: (5) | K15: (6) | N15: INTRVENSI ATASAN | O15: HASIL KERJA
B16: A. | C16: UTAMA
B17: 1 | C17: =IF(N17<>"",VLOOKUP(N17,TUPOKSI!$B$6:$C$42,2,FALSE),"") -> Meningkatnya aksesibilitas dan kualitas Pendidikan Dasar Dinas Pendidikan Kab. Lampung Utara | D17: =IF(O17<>"",VLOOKUP(O17,TUPOKSI!$E$6:$F$42,2,FALSE),"") -> Dokumen Program Kerja Sekolah dalam bidang Manajerial, Kewirausahaan, Supervisi Guru dan Tendik dalam penyelenggaraan dan atau pengelolaan Sekolah. | G17: Kuantitas | H17: Jumlah Dokumen Program | J17: 2 | K17: Dokumen | N17: 1.1 | O17: 4.1
G18: Kualitas | H18: Program Pengawasan dan Program Bimlat Guru / Kepala Sekolah. | J18: 0.95 | K18: (Persen)
G19: Waktu | H19: Ketepatan waktu pelaksanaan kegiatan. | J19: 1 | K19: Bulan
B20: 2 | C20: =IF(N20<>"",VLOOKUP(N20,TUPOKSI!$B$6:$C$42,2,FALSE),"") -> Meningkatnya aksesibilitas dan kualitas Pendidikan Dasar Dinas Pendidikan Kab. Lampung Utara | D20: =IF(O20<>"",VLOOKUP(O20,TUPOKSI!$E$6:$F$42,2,FALSE),"") -> Laporan pelaksanaan tugas pokok kepala sekolah (Manajerial, Kewirausahaan, Supervisi Guru dan Tendik) dalam penyelenggaraan dan atau pengelolaan Sekolah. | G20: Kuantitas | H20: Jumlah Laporan Pengawasan | J20: 1 | K20: Laporan | N20: 1.1 | O20: 4.2
G21: Kualitas | H21: Materi Pengawasan, instrumen, daftar hadir, suket kegiatan dari KS. | J21: 0.95 | K21: (Persen)
G22: Waktu | H22: Ketepatan waktu pelaksanaan kegiatan. | J22: 12 | K22: Bulan
B23: 3 | C23: =IF(N23<>"",VLOOKUP(N23,TUPOKSI!$B$6:$C$42,2,FALSE),"") -> Laporan Pelaksanaan kegiatan Program Peningkatan aksesibilitas dan kualitas pendidikan Dinas Pendidikan Kab. Lampung Utara | D23: =IF(O23<>"",VLOOKUP(O23,TUPOKSI!$E$6:$F$42,2,FALSE),"") -> Laporan Evaluasi dan ketercapaian program kerja pelaksanaan tugas pokok kepala sekolah (Manajerial, Kewirausahaan, Supervisi) dalam bentuk EDS dan atau Analisis Hasil Rapor Pendidikan (PBD). | G23: Kuantitas | H23: Jumlah Laporan Bimlat Guru dan KS. | J23: 1 | K23: Laporan | N23: 1.2 | O23: 4.3
G24: Kualitas | H24: Materi Instrumen Pengawasan sekolah, daftar hadir, suket dari KS. | J24: 0.95 | K24: (Persen)
G25: Waktu | H25: Ketepatan waktu pelaksanaan kegiatan. | J25: 6 | K25: Bulan
B26: 4 | C26: =IF(N26<>"",VLOOKUP(N26,TUPOKSI!$B$6:$C$42,2,FALSE),"") -> Laporan Evaluasi Hasil Program Peningkatan aksesibilitas dan kualitas sesuai peraturan yang berlaku secara efektif dan efisien. | D26: =IF(O26<>"",VLOOKUP(O26,TUPOKSI!$E$6:$F$42,2,FALSE),"") -> Laporan Pengembangan Keprofesian Berkelanjutan Kepala Sekolah dalam bentuk Diklat fungsional kepala sekolah dan atau Karya Tulis Ilmiah Kepala Sekolah. | G26: Kuantitas | H26: Jumlah Laporan Evaluasi Pengawasan | J26: 1 | K26: Laporan | N26: 1.3 | O26: 4.4
G27: Kualitas | H27: Instrumen Evaluasi Pengawasan, dafhad, suket kegiatan dari KS. | J27: 0.95 | K27: (Persen)
G28: Waktu | H28: Ketepatan waktu pelaksanaan kegiatan. | J28: 2 | K28: Bulan
B29: 5 | C29: =IF(N29<>"",VLOOKUP(N29,TUPOKSI!$B$6:$C$42,2,FALSE),"") -> Dokumen kegiatan peningkatan kompetensi dan pengembangan karir ASN di lingkungan Dinas Pendidikan Kab. Lampung Utara | D29: =IF(O29<>"",VLOOKUP(O29,TUPOKSI!$E$6:$F$42,2,FALSE),"") -> Dokumen kegiatan tugas tambahan sebagai Pengurus atau MKKS/KKKS Kab. Lampung Utara | G29: Kuantitas | H29: Jumlah Laporan Pengembangan Diri | J29: 1 | K29: Laporan | N29: 1.5 | O29: 4.5
G30: Kualitas | H30: Laporan PD, daftar hadir, suket kegiatan dari Korwas. | J30: 0.95 | K30: (Persen)
G31: Waktu | H31: Ketepatan waktu pelaksanaan kegiatan. | J31: 3 | K31: Bulan
B32: B. | C32: TAMBAHAN
B33: 1 | C33: =IF(N33<>"",VLOOKUP(N33,TUPOKSI!$B$6:$C$42,2,FALSE),"") -> Dokumen tugas kedinasan lain yang diberikan pimpinan baik lisan maupun tertulis dilingkungan Dinas Pendidikan Kab. Lampung Utara | D33: =IF(O33<>"",VLOOKUP(O33,TUPOKSI!$E$6:$F$42,2,FALSE),"") -> Dokumen kegiatan tugas tambahan sebagai Anggota / Pengurus MKKS/PGRI Kab. Barito Timur. | G33: Kuantitas | H33: Jumlah Satuan Kegiatan | J33: 1 | K33: Dokumen | N33: 1.4 | O33: 4.6
G34: Kualitas | H34: Dokumen Tugas Tambahan sebagai Pengurus APSI | J34: 0.95 | K34: (Persen)
G35: Waktu | H35: Ketepatan waktu pelaksanaan kegiatan. | J35: 12 | K35: Bulan
B36: 2 | C36: =IF(N36<>"",VLOOKUP(N36,TUPOKSI!$B$6:$C$42,2,FALSE),"") -> Dokumen kegiatan peningkatan kompetensi dan pengembangan karir ASN di lingkungan Dinas Pendidikan Kab. Lampung Utara | D36: =IF(O36<>"",VLOOKUP(O36,TUPOKSI!$E$6:$F$42,2,FALSE),"") -> Dokumen kegiatan mengikuti Seminar dan atau Webinar Pendidikan di Lingkungan daerah dan Pusat. | G36: Kuantitas | H36: Jumlah Sertifikat | J36: 1 | K36: Sertifikat | N36: 1.5 | O36: 4.7
G37: Kualitas | H37: Sertifikat Webinar APSI Pusat sebagai peserta | J37: 0.95 | K37: (Persen)
G38: Waktu | H38: Ketepatan waktu pelaksanaan kegiatan. | J38: 6 | K38: Bulan | N38: KONDISI IDEAL
F39: PERILAKU KERJA | N39: KD PRLKU | O39: EXPTASI
B40: 1 | C40: =IF(N40<>"",VLOOKUP(N40,BERAHLAK!$B$5:$C$53,2,FALSE),"") -> Berorientasi Pelayanan | N40: 1.
C41: =IF(N41<>"",VLOOKUP(N41,BERAHLAK!$B$5:$C$53,2,FALSE),"") -> - Memahami dan memenuhi kebutuhan masyarakat | F41: Ekspektasi Khusus Pimpinan: | N41: 1.1
...

Sheet EVALUASI KINERJA KUANTI JF (2)
A1: ='EVALUASI KINERJA KUANTI JF'!A1&"" -> A | O1: HOME
B2: EVALUASI KINERJA PEGAWAI
B3: ='SKP JF (KUANTITATIF)'!B3&"" -> JABATAN FUNGSIONAL KEPALA SEKOLAH
B4: PENDEKATAN HASIL KERJA KUANTITATIF
B6: PERIODE: TRIWULAN I/II/III/IV-AKHIR*
B7: ='SKP JF (KUANTITATIF)'!B6&"" -> DINAS PENDIDIKAN KAB. LAMPUNG UTARA | H7: PERIODE PENILAIAN: | K7: ='SKP JF (KUANTITATIF)'!H6&"" -> 01 JANUARI 2022 S.D 31 DESEMBER 2022
B8: NO. | C8: PEGAWAI YANG DINILAI | H8: NO. | I8: PEJABAT PENILAI KINERJA
B9: 1 | C9: NAMA | E9: ='SKP JF (KUANTITATIF)'!D8&"" -> RUSLAN, S.Pd | H9: 1 | I9: NAMA | L9: =IF(A1="A",'00 DATA'!F12,IF(A1="B",'00 DATA'!N20,"")) -> TUTI ROSPASARI, S.Pd. M.Pd.
B10: 2 | C10: NIP | E10: ='SKP JF (KUANTITATIF)'!D9&"" -> 19660625 199112 1 001 | H10: 2 | I10: NIP | L10: =IF(A1="A",'00 DATA'!F13,IF(A1="B",'00 DATA'!N21,"")) -> 19721025 199802 2 003
B11: 3 | C11: PANGKAT/GOL. RUANG | E11: ='SKP JF (KUANTITATIF)'!D10&"" -> PEMBINA TK.I/ IV.b | H11: 3 | I11: PANGKAT/GOL.RUANG | L11: =IF(A1="A",'00 DATA'!F14,IF(A1="B",'00 DATA'!N22,"")) -> PEMBINA TK.I (IV/b)
B12: 4 | C12: JABATAN | E12: ='SKP JF (KUANTITATIF)'!D11&"" -> KEPALA SEKOLAH | H12: 4 | I12: JABATAN | L12: =IF(A1="A",'00 DATA'!F15,IF(A1="B",'00 DATA'!N23,"")) -> SEKRETARIS DINAS
B13: 5 | C13: UNIT KERJA | E13: ='SKP JF (KUANTITATIF)'!D12&"" -> UPTD SDN 1 KOTABUMI TENGAH KAB. LAMPUNG UTARA | H13: 5 | I13: INSTANSI | L13: =IF(A1="A",'00 DATA'!F16&" "&'00 DATA'!D17&" "&'00 DATA'!F17&"",IF(A1="B",'00 DATA'!N24&" "&'00 DATA'!L25&" "&'00 DATA'!N25,"")) -> DINAS PENDIDIKAN KAB. LAMPUNG UTARA
B14: CAPAIAN KINERJA ORGANISASI*
B15: ='EVALUASI KINERJA KUANTI JF'!B15&"" -> BAIK
B16: POLA DISTRIBUSI:
B18: HASIL KERJA
B19: NO. | C19: RENCANA HASIL KERJA PIMPINAN YANG DIINTERVENSI | D19: RENCANA HASIL KERJA | F19: ASPEK | G19: INDIKATOR KINERJA INDIVIDU | J19: TARGET | K19: REALISASI BERDASARKAN BUKTI DUKUNG | M19: UMPAN BALIK BERKELANJUTAN BERDASARKAN BUKTI DUKUNG
B20: (1) | C20: (2) | D20: (3) | F20: (4) | G20: (5) | J20: (6) | K20: (7) | N20: (8)
B21: A. UTAMA | S21: 91-100 | T21: 76-90 | U21: 61-75 | V21: 51-60
B22: ='SKP JF (KUANTITATIF)'!B17&"" -> 1 | C22: ='SKP JF (KUANTITATIF)'!C17&"" -> Meningkatnya aksesibilitas dan kualitas Pendidikan Dasar Dinas Pendidikan Kab. Lampung Utara | D22: ='SKP JF (KUANTITATIF)'!D17&"" -> Dokumen Program Kerja Sekolah dalam bidang Manajerial, Kewirausahaan, Supervisi Guru dan Tendik dalam penyelenggaraan dan atau pengelolaan Sekolah. | F22: ='SKP JF (KUANTITATIF)'!G17&"" -> Kuantitas | G22: ='SKP JF (KUANTITATIF)'!H17&"" -> Jumlah Dokumen Program | I22: ='SKP JF (KUANTITATIF)'!J17&"" -> 2 | J22: ='SKP JF (KUANTITATIF)'!K17&"" -> Dokumen | K22: ='EVALUASI KINERJA KUANTI JF'!K22&"" -> 2 | L22: ='EVALUASI KINERJA KUANTI JF'!L22&"" -> berdasarkan penilaian pimpinan | M22: =IF(Q22="Sangat Baik","C",IF(Q22="Baik","J",IF(Q22="Cukup","K",IF(Q22="Kurang","L","")))) -> C | N22: =IF(K22="","",IF(Q22="Sangat Baik","Bagus, sudah amat baik, pertahankan.",IF(Q22="Baik","Bagus, sudah baik, dapat lebih ditingkatkan.",IF(Q22="Cukup","Cukup baik, ada baiknya perlu sekali ditingkatkan.",IF(Q22="Kurang","Kurang, sangat perlu perbaikan secara menyeluruh.",""))))) -> Bagus, sudah amat baik, pertahankan. | P22: =(K22/I22)*100 -> 100 | Q22: =IF(P22<=50,("Buruk"),IF(P22<=60,("Kurang"),IF(P22<=75,("Cukup"),IF(P22<=90,("Baik"),("Sangat Baik"))))) -> Sangat Baik | S22: C | T22: J | U22: K | V22: L
F23: ='SKP JF (KUANTITATIF)'!G18&"" -> Kualitas | G23: ='SKP JF (KUANTITATIF)'!H18&"" -> Program Pengawasan dan Program Bimlat Guru / Kepala Sekolah. | I23: ='SKP JF (KUANTITATIF)'!J18 -> 0.95 | J23: ='SKP JF (KUANTITATIF)'!K18&"" -> (Persen) | K23: ='EVALUASI KINERJA KUANTI JF'!K23 -> 0.9 | L23: =IF(K23>=1%,"berdasarkan penilaian pimpinan","") -> berdasarkan penilaian pimpinan | M23: =IF(Q23="Sangat Baik","C",IF(Q23="Baik","J",IF(Q23="Cukup","K",IF(Q23="Kurang","L","")))) -> C | N23: =IF(K23="","",IF(Q23="Sangat Baik","Bagus, sudah amat baik, pertahankan.",IF(Q23="Baik","Bagus, sudah baik, dapat lebih ditingkatkan.",IF(Q23="Cukup","Cukup baik, ada baiknya perlu sekali ditingkatkan.",IF(Q23="Kurang","Kurang, sangat perlu perbaikan secara menyeluruh.",""))))) -> Bagus, sudah amat baik, pertahankan. | P23: =(K23/I23)*100 -> 94.736842 | Q23: =IF(P23<=50,("Buruk"),IF(P23<=60,("Kurang"),IF(P23<=75,("Cukup"),IF(P23<=90,("Baik"),("Sangat Baik"))))) -> Sangat Baik | S23: Sangat Baik | T23: Baik | U23: Cukup | V23: Kurang
F24: ='SKP JF (KUANTITATIF)'!G19&"" -> Waktu | G24: ='SKP JF (KUANTITATIF)'!H19&"" -> Ketepatan waktu pelaksanaan kegiatan. | I24: ='SKP JF (KUANTITATIF)'!J19 -> 1 | J24: ='SKP JF (KUANTITATIF)'!K19&"" -> Bulan | K24: ='EVALUASI KINERJA KUANTI JF'!K24&"" -> 1 | L24: ='EVALUASI KINERJA KUANTI JF'!L24&"" -> bulan berdasarkan waktu kegiatan | M24: =IF(Q24="Sangat Baik","C",IF(Q24="Baik","J",IF(Q24="Cukup","K",IF(Q24="Kurang","L","")))) -> C | N24: =IF(K24="","",IF(Q24="Sangat Baik","Bagus, sudah amat baik, pertahankan.",IF(Q24="Baik","Bagus, sudah baik, dapat lebih ditingkatkan.",IF(Q24="Cukup","Cukup baik, ada baiknya perlu sekali ditingkatkan.",IF(Q24="Kurang","Kurang, sangat perlu perbaikan secara menyeluruh.",""))))) -> Bagus, sudah amat baik, pertahankan. | P24: =(K24/I24)*100 -> 100 | Q24: =IF(P24<=50,("Buruk"),IF(P24<=60,("Kurang"),IF(P24<=75,("Cukup"),IF(P24<=90,("Baik"),("Sangat Baik"))))) -> Sangat Baik | T24: Chek | U24: 91 | V24: =IF(U24<=50,("Buruk"),IF(U24<=60,("Kurang"),IF(U24<=75,("Cukup"),IF(U24<=90,("Baik"),("Sangat Baik"))))) -> Sangat Baik
B25: ='SKP JF (KUANTITATIF)'!B20&"" -> 2 | C25: ='SKP JF (KUANTITATIF)'!C20&"" -> Meningkatnya aksesibilitas dan kualitas Pendidikan Dasar Dinas Pendidikan Kab. Lampung Utara | D25: ='SKP JF (KUANTITATIF)'!D20&"" -> Laporan pelaksanaan tugas pokok kepala sekolah (Manajerial, Kewirausahaan, Supervisi Guru dan Tendik) dalam penyelenggaraan dan atau pengelolaan Sekolah. | F25: ='SKP JF (KUANTITATIF)'!G20&"" -> Kuantitas | G25: ='SKP JF (KUANTITATIF)'!H20&"" -> Jumlah Laporan Pengawasan | I25: ='SKP JF (KUANTITATIF)'!J20 -> 1 | J25: ='SKP JF (KUANTITATIF)'!K20&"" -> Laporan | K25: ='EVALUASI KINERJA KUANTI JF'!K25&"" -> 1 | L25: ='EVALUASI KINERJA KUANTI JF'!L25&"" -> berdasarkan penilaian pimpinan | M25: =IF(Q25="Sangat Baik","C",IF(Q25="Baik","J",IF(Q25="Cukup","K",IF(Q25="Kurang","L","")))) -> C | N25: =IF(K25="","",IF(Q25="Sangat Baik","Bagus, sudah amat baik, pertahankan.",IF(Q25="Baik","Bagus, sudah baik, dapat lebih ditingkatkan.",IF(Q25="Cukup","Cukup baik, ada baiknya perlu sekali ditingkatkan.",IF(Q25="Kurang","Kurang, sangat perlu perbaikan secara menyeluruh.",""))))) -> Bagus, sudah amat baik, pertahankan. | P25: =(K25/I25)*100 -> 100 | Q25: =IF(P25<=50,("Buruk"),IF(P25<=60,("Kurang"),IF(P25<=75,("Cukup"),IF(P25<=90,("Baik"),("Sangat Baik"))))) -> Sangat Baik
F26: ='SKP JF (KUANTITATIF)'!G21&"" -> Kualitas | G26: ='SKP JF (KUANTITATIF)'!H21&"" -> Materi Pengawasan, instrumen, daftar hadir, suket kegiatan dari KS. | I26: ='SKP JF (KUANTITATIF)'!J21 -> 0.95 | J26: ='SKP JF (KUANTITATIF)'!K21&"" -> (Persen) | K26: ='EVALUASI KINERJA KUANTI JF'!K26 -> 0.9 | L26: =IF(K26>=1%,"berdasarkan penilaian pimpinan","") -> berdasarkan penilaian pimpinan | M26: =IF(Q26="Sangat Baik","C",IF(Q26="Baik","J",IF(Q26="Cukup","K",IF(Q26="Kurang","L","")))) -> C | N26: =IF(K26="","",IF(Q26="Sangat Baik","Bagus, sudah amat baik, pertahankan.",IF(Q26="Baik","Bagus, sudah baik, dapat lebih ditingkatkan.",IF(Q26="Cukup","Cukup baik, ada baiknya perlu sekali ditingkatkan.",IF(Q26="Kurang","Kurang, sangat perlu perbaikan secara menyeluruh.",""))))) -> Bagus, sudah amat baik, pertahankan. | P26: =(K26/I26)*100 -> 94.736842 | Q26: =IF(P26<=50,("Buruk"),IF(P26<=60,("Kurang"),IF(P26<=75,("Cukup"),IF(P26<=90,("Baik"),("Sangat Baik"))))) -> Sangat Baik
F27: ='SKP JF (KUANTITATIF)'!G22&"" -> Waktu | G27: ='SKP JF (KUANTITATIF)'!H22&"" -> Ketepatan waktu pelaksanaan kegiatan. | I27: ='SKP JF (KUANTITATIF)'!J22 -> 12 | J27: ='SKP JF (KUANTITATIF)'!K22&"" -> Bulan | K27: ='EVALUASI KINERJA KUANTI JF'!K27&"" -> 12 | L27: ='EVALUASI KINERJA KUANTI JF'!L27&"" -> bulan berdasarkan waktu kegiatan | M27: =IF(Q27="Sangat Baik","C",IF(Q27="Baik","J",IF(Q27="Cukup","K",IF(Q27="Kurang","L","")))) -> C | N27: =IF(K27="","",IF(Q27="Sangat Baik","Bagus, sudah amat baik, pertahankan.",IF(Q27="Baik","Bagus, sudah baik, dapat lebih ditingkatkan.",IF(Q27="Cukup","Cukup baik, ada baiknya perlu sekali ditingkatkan.",IF(Q27="Kurang","Kurang, sangat perlu perbaikan secara menyeluruh.",""))))) -> Bagus, sudah amat baik, pertahankan. | P27: =(K27/I27)*100 -> 100 | Q27: =IF(P27<=50,("Buruk"),IF(P27<=60,("Kurang"),IF(P27<=75,("Cukup"),IF(P27<=90,("Baik"),("Sangat Baik"))))) -> Sangat Baik
B28: ='SKP JF (KUANTITATIF)'!B23&"" -> 3 | C28: ='SKP JF (KUANTITATIF)'!C23&"" -> Laporan Pelaksanaan kegiatan Program Peningkatan aksesibilitas dan kualitas pendidikan Dinas Pendidikan Kab. Lampung Utara | D28: ='SKP JF (KUANTITATIF)'!D23&"" -> Laporan Evaluasi dan ketercapaian program kerja pelaksanaan tugas pokok kepala sekolah (Manajerial, Kewirausahaan, Supervisi) dalam bentuk EDS dan atau Analisis Hasil Rapor Pendidikan (PBD). | F28: ='SKP JF (KUANTITATIF)'!G23&"" -> Kuantitas | G28: ='SKP JF (KUANTITATIF)'!H23&"" -> Jumlah Laporan Bimlat Guru dan KS. | I28: ='SKP JF (KUANTITATIF)'!J23 -> 1 | J28: ='SKP JF (KUANTITATIF)'!K23&"" -> Laporan | K28: ='EVALUASI KINERJA KUANTI JF'!K28&"" -> 1 | L28: ='EVALUASI KINERJA KUANTI JF'!L28&"" -> berdasarkan penilaian pimpinan | M28: =IF(Q28="Sangat Baik","C",IF(Q28="Baik","J",IF(Q28="Cukup","K",IF(Q28="Kurang","L","")))) -> C | N28: =IF(K28="","",IF(Q28="Sangat Baik","Bagus, sudah amat baik, pertahankan.",IF(Q28="Baik","Bagus, sudah baik, dapat lebih ditingkatkan.",IF(Q28="Cukup","Cukup baik, ada baiknya perlu sekali ditingkatkan.",IF(Q28="Kurang","Kurang, sangat perlu perbaikan secara menyeluruh.",""))))) -> Bagus, sudah amat baik, pertahankan. | P28: =(K28/I28)*100 -> 100 | Q28: =IF(P28<=50,("Buruk"),IF(P28<=60,("Kurang"),IF(P28<=75,("Cukup"),IF(P28<=90,("Baik"),("Sangat Baik"))))) -> Sangat Baik
F29: ='SKP JF (KUANTITATIF)'!G24&"" -> Kualitas | G29: ='SKP JF (KUANTITATIF)'!H24&"" -> Materi Instrumen Pengawasan sekolah, daftar hadir, suket dari KS. | I29: ='SKP JF (KUANTITATIF)'!J24 -> 0.95 | J29: ='SKP JF (KUANTITATIF)'!K24&"" -> (Persen) | K29: ='EVALUASI KINERJA KUANTI JF'!K29 -> 0.9 | L29: =IF(K29>=1%,"berdasarkan penilaian pimpinan","") -> berdasarkan penilaian pimpinan | M29: =IF(Q29="Sangat Baik","C",IF(Q29="Baik","J",IF(Q29="Cukup","K",IF(Q29="Kurang","L","")))) -> C | N29: =IF(K29="","",IF(Q29="Sangat Baik","Bagus, sudah amat baik, pertahankan.",IF(Q29="Baik","Bagus, sudah baik, dapat lebih ditingkatkan.",IF(Q29="Cukup","Cukup baik, ada baiknya perlu sekali ditingkatkan.",IF(Q29="Kurang","Kurang, sangat perlu perbaikan secara menyeluruh.",""))))) -> Bagus, sudah amat baik, pertahankan. | P29: =(K29/I29)*100 -> 94.736842 | Q29: =IF(P29<=50,("Buruk"),IF(P29<=60,("Kurang"),IF(P29<=75,("Cukup"),IF(P29<=90,("Baik"),("Sangat Baik"))))) -> Sangat Baik
F30: ='SKP JF (KUANTITATIF)'!G25&"" -> Waktu | G30: ='SKP JF (KUANTITATIF)'!H25&"" -> Ketepatan waktu pelaksanaan kegiatan. | I30: ='SKP JF (KUANTITATIF)'!J25 -> 6 | J30: ='SKP JF (KUANTITATIF)'!K25&"" -> Bulan | K30: ='EVALUASI KINERJA KUANTI JF'!K30&"" -> 6 | L30: ='EVALUASI KINERJA KUANTI JF'!L30&"" -> bulan berdasarkan waktu kegiatan | M30: =IF(Q30="Sangat Baik","C",IF(Q30="Baik","J",IF(Q30="Cukup","K",IF(Q30="Kurang","L","")))) -> C | N30: =IF(K30="","",IF(Q30="Sangat Baik","Bagus, sudah amat baik, pertahankan.",IF(Q30="Baik","Bagus, sudah baik, dapat lebih ditingkatkan.",IF(Q30="Cukup","Cukup baik, ada baiknya perlu sekali ditingkatkan.",IF(Q30="Kurang","Kurang, sangat perlu perbaikan secara menyeluruh.",""))))) -> Bagus, sudah amat baik, pertahankan. | P30: =(K30/I30)*100 -> 100 | Q30: =IF(P30<=50,("Buruk"),IF(P30<=60,("Kurang"),IF(P30<=75,("Cukup"),IF(P30<=90,("Baik"),("Sangat Baik"))))) -> Sangat Baik
B31: ='SKP JF (KUANTITATIF)'!B26&"" -> 4 | C31: ='SKP JF (KUANTITATIF)'!C26&"" -> Laporan Evaluasi Hasil Program Peningkatan aksesibilitas dan kualitas sesuai peraturan yang berlaku secara efektif dan efisien. | D31: ='SKP JF (KUANTITATIF)'!D26&"" -> Laporan Pengembangan Keprofesian Berkelanjutan Kepala Sekolah dalam bentuk Diklat fungsional kepala sekolah dan atau Karya Tulis Ilmiah Kepala Sekolah. | F31: ='SKP JF (KUANTITATIF)'!G26&"" -> Kuantitas | G31: ='SKP JF (KUANTITATIF)'!H26&"" -> Jumlah Laporan Evaluasi Pengawasan | I31: ='SKP JF (KUANTITATIF)'!J26 -> 1 | J31: ='SKP JF (KUANTITATIF)'!K26&"" -> Laporan | K31: ='EVALUASI KINERJA KUANTI JF'!K31&"" -> 1 | L31: ='EVALUASI KINERJA KUANTI JF'!L31&"" -> berdasarkan penilaian pimpinan | M31: =IF(Q31="Sangat Baik","C",IF(Q31="Baik","J",IF(Q31="Cukup","K",IF(Q31="Kurang","L","")))) -> C | N31: =IF(K31="","",IF(Q31="Sangat Baik","Bagus, sudah amat baik, pertahankan.",IF(Q31="Baik","Bagus, sudah baik, dapat lebih ditingkatkan.",IF(Q31="Cukup","Cukup baik, ada baiknya perlu sekali ditingkatkan.",IF(Q31="Kurang","Kurang, sangat perlu perbaikan secara menyeluruh.",""))))) -> Bagus, sudah amat baik, pertahankan. | P31: =(K31/I31)*100 -> 100 | Q31: =IF(P31<=50,("Buruk"),IF(P31<=60,("Kurang"),IF(P31<=75,("Cukup"),IF(P31<=90,("Baik"),("Sangat Baik"))))) -> Sangat Baik
F32: ='SKP JF (KUANTITATIF)'!G27&"" -> Kualitas | G32: ='SKP JF (KUANTITATIF)'!H27&"" -> Instrumen Evaluasi Pengawasan, dafhad, suket kegiatan dari KS. | I32: ='SKP JF (KUANTITATIF)'!J27 -> 0.95 | J32: ='SKP JF (KUANTITATIF)'!K27&"" -> (Persen) | K32: ='EVALUASI KINERJA KUANTI JF'!K32 -> 0.85 | L32: =IF(K32>=1%,"berdasarkan penilaian pimpinan","") -> berdasarkan penilaian pimpinan | M32: =IF(Q32="Sangat Baik","C",IF(Q32="Baik","J",IF(Q32="Cukup","K",IF(Q32="Kurang","L","")))) -> J | N32: =IF(K32="","",IF(Q32="Sangat Baik","Bagus, sudah amat baik, pertahankan.",IF(Q32="Baik","Bagus, sudah baik, dapat lebih ditingkatkan.",IF(Q32="Cukup","Cukup baik, ada baiknya perlu sekali ditingkatkan.",IF(Q32="Kurang","Kurang, sangat perlu perbaikan secara menyeluruh.",""))))) -> Bagus, sudah baik, dapat lebih ditingkatkan. | P32: =(K32/I32)*100 -> 89.473684 | Q32: =IF(P32<=50,("Buruk"),IF(P32<=60,("Kurang"),IF(P32<=75,("Cukup"),IF(P32<=90,("Baik"),("Sangat Baik"))))) -> Baik
F33: ='SKP JF (KUANTITATIF)'!G28&"" -> Waktu | G33: ='SKP JF (KUANTITATIF)'!H28&"" -> Ketepatan waktu pelaksanaan kegiatan. | I33: ='SKP JF (KUANTITATIF)'!J28 -> 2 | J33: ='SKP JF (KUANTITATIF)'!K28&"" -> Bulan | K33: ='EVALUASI KINERJA KUANTI JF'!K33&"" -> 2 | L33: ='EVALUASI KINERJA KUANTI JF'!L33&"" -> bulan berdasarkan waktu kegiatan | M33: =IF(Q33="Sangat Baik","C",IF(Q33="Baik","J",IF(Q33="Cukup","K",IF(Q33="Kurang","L","")))) -> C | N33: =IF(K33="","",IF(Q33="Sangat Baik","Bagus, sudah amat baik, pertahankan.",IF(Q33="Baik","Bagus, sudah baik, dapat lebih ditingkatkan.",IF(Q33="Cukup","Cukup baik, ada baiknya perlu sekali ditingkatkan.",IF(Q33="Kurang","Kurang, sangat perlu perbaikan secara menyeluruh.",""))))) -> Bagus, sudah amat baik, pertahankan. | P33: =(K33/I33)*100 -> 100 | Q33: =IF(P33<=50,("Buruk"),IF(P33<=60,("Kurang"),IF(P33<=75,("Cukup"),IF(P33<=90,("Baik"),("Sangat Baik"))))) -> Sangat Baik
B34: ='SKP JF (KUANTITATIF)'!B29&"" -> 5 | C34: ='SKP JF (KUANTITATIF)'!C29&"" -> Dokumen kegiatan peningkatan kompetensi dan pengembangan karir ASN di lingkungan Dinas Pendidikan Kab. Lampung Utara | D34: ='SKP JF (KUANTITATIF)'!D29&"" -> Dokumen kegiatan tugas tambahan sebagai Pengurus atau MKKS/KKKS Kab. Lampung Utara | F34: ='SKP JF (KUANTITATIF)'!G29&"" -> Kuantitas | G34: ='SKP JF (KUANTITATIF)'!H29&"" -> Jumlah Laporan Pengembangan Diri | I34: ='SKP JF (KUANTITATIF)'!J29 -> 1 | J34: ='SKP JF (KUANTITATIF)'!K29&"" -> Laporan | K34: ='EVALUASI KINERJA KUANTI JF'!K34&"" -> 1 | L34: ='EVALUASI KINERJA KUANTI JF'!L34&"" -> berdasarkan penilaian pimpinan | M34: =IF(Q34="Sangat Baik","C",IF(Q34="Baik","J",IF(Q34="Cukup","K",IF(Q34="Kurang","L","")))) -> C | N34: =IF(K34="","",IF(Q34="Sangat Baik","Bagus, sudah amat baik, pertahankan.",IF(Q34="Baik","Bagus, sudah baik, dapat lebih ditingkatkan.",IF(Q34="Cukup","Cukup baik, ada baiknya perlu sekali ditingkatkan.",IF(Q34="Kurang","Kurang, sangat perlu perbaikan secara menyeluruh.",""))))) -> Bagus, sudah amat baik, pertahankan. | P34: =(K34/I34)*100 -> 100 | Q34: =IF(P34<=50,("Buruk"),IF(P34<=60,("Kurang"),IF(P34<=75,("Cukup"),IF(P34<=90,("Baik"),("Sangat Baik"))))) -> Sangat Baik
F35: ='SKP JF (KUANTITATIF)'!G30&"" -> Kualitas | G35: ='SKP JF (KUANTITATIF)'!H30&"" -> Laporan PD, daftar hadir, suket kegiatan dari Korwas. | I35: ='SKP JF (KUANTITATIF)'!J30 -> 0.95 | J35: ='SKP JF (KUANTITATIF)'!K30&"" -> (Persen) | K35: ='EVALUASI KINERJA KUANTI JF'!K35 -> 0.9 | L35: =IF(K35>=1%,"berdasarkan penilaian pimpinan","") -> berdasarkan penilaian pimpinan | M35: =IF(Q35="Sangat Baik","C",IF(Q35="Baik","J",IF(Q35="Cukup","K",IF(Q35="Kurang","L","")))) -> C | N35: =IF(K35="","",IF(Q35="Sangat Baik","Bagus, sudah amat baik, pertahankan.",IF(Q35="Baik","Bagus, sudah baik, dapat lebih ditingkatkan.",IF(Q35="Cukup","Cukup baik, ada baiknya perlu sekali ditingkatkan.",IF(Q35="Kurang","Kurang, sangat perlu perbaikan secara menyeluruh.",""))))) -> Bagus, sudah amat baik, pertahankan. | P35: =(K35/I35)*100 -> 94.736842 | Q35: =IF(P35<=50,("Buruk"),IF(P35<=60,("Kurang"),IF(P35<=75,("Cukup"),IF(P35<=90,("Baik"),("Sangat Baik"))))) -> Sangat Baik
F36: ='SKP JF (KUANTITATIF)'!G31&"" -> Waktu | G36: ='SKP JF (KUANTITATIF)'!H31&"" -> Ketepatan waktu pelaksanaan kegiatan. | I36: ='SKP JF (KUANTITATIF)'!J31 -> 3 | J36: ='SKP JF (KUANTITATIF)'!K31&"" -> Bulan | K36: ='EVALUASI KINERJA KUANTI JF'!K36&"" -> 3 | L36: ='EVALUASI KINERJA KUANTI JF'!L36&"" -> bulan berdasarkan waktu kegiatan | M36: =IF(Q36="Sangat Baik","C",IF(Q36="Baik","J",IF(Q36="Cukup","K",IF(Q36="Kurang","L","")))) -> C | N36: =IF(K36="","",IF(Q36="Sangat Baik","Bagus, sudah amat baik, pertahankan.",IF(Q36="Baik","Bagus, sudah baik, dapat lebih ditingkatkan.",IF(Q36="Cukup","Cukup baik, ada baiknya perlu sekali ditingkatkan.",IF(Q36="Kurang","Kurang, sangat perlu perbaikan secara menyeluruh.",""))))) -> Bagus, sudah amat baik, pertahankan. | P36: =(K36/I36)*100 -> 100 | Q36: =IF(P36<=50,("Buruk"),IF(P36<=60,("Kurang"),IF(P36<=75,("Cukup"),IF(P36<=90,("Baik"),("Sangat Baik"))))) -> Sangat Baik
B37: B. TAMBAHAN
B38: ='SKP JF (KUANTITATIF)'!B33&"" -> 1 | C38: ='SKP JF (KUANTITATIF)'!C33&"" -> Dokumen tugas kedinasan lain yang diberikan pimpinan baik lisan maupun tertulis dilingkungan Dinas Pendidikan Kab. Lampung Utara | D38: ='SKP JF (KUANTITATIF)'!D33&"" -> Dokumen kegiatan tugas tambahan sebagai Anggota / Pengurus MKKS/PGRI Kab. Barito Timur. | F38: ='SKP JF (KUANTITATIF)'!G33&"" -> Kuantitas | G38: ='SKP JF (KUANTITATIF)'!H33&"" -> Jumlah Satuan Kegiatan | I38: ='SKP JF (KUANTITATIF)'!J33 -> 1 | J38: ='SKP JF (KUANTITATIF)'!K33&"" -> Dokumen | K38: ='EVALUASI KINERJA KUANTI JF'!K38&"" -> 1 | L38: ='EVALUASI KINERJA KUANTI JF'!L38&"" -> berdasarkan penilaian pimpinan | M38: =IF(Q38="Sangat Baik","C",IF(Q38="Baik","J",IF(Q38="Cukup","K",IF(Q38="Kurang","L","")))) -> C | N38: =IF(K38="","",IF(Q38="Sangat Baik","Bagus, sudah amat baik, pertahankan.",IF(Q38="Baik","Bagus, sudah baik, dapat lebih ditingkatkan.",IF(Q38="Cukup","Cukup baik, ada baiknya perlu sekali ditingkatkan.",IF(Q38="Kurang","Kurang, sangat perlu perbaikan secara menyeluruh.",""))))) -> Bagus, sudah amat baik, pertahankan. | P38: =(K38/I38)*100 -> 100 | Q38: =IF(P38<=50,("Buruk"),IF(P38<=60,("Kurang"),IF(P38<=75,("Cukup"),IF(P38<=90,("Baik"),("Sangat Baik"))))) -> Sangat Baik
F39: ='SKP JF (KUANTITATIF)'!G34&"" -> Kualitas | G39: ='SKP JF (KUANTITATIF)'!H34&"" -> Dokumen Tugas Tambahan sebagai Pengurus APSI | I39: ='SKP JF (KUANTITATIF)'!J34 -> 0.95 | J39: ='SKP JF (KUANTITATIF)'!K34&"" -> (Persen) | K39: ='EVALUASI KINERJA KUANTI JF'!K39 -> 0.9 | L39: =IF(K39>=1%,"berdasarkan penilaian pimpinan","") -> berdasarkan penilaian pimpinan | M39: =IF(Q39="Sangat Baik","C",IF(Q39="Baik","J",IF(Q39="Cukup","K",IF(Q39="Kurang","L","")))) -> C | N39: =IF(K39="","",IF(Q39="Sangat Baik","Bagus, sudah amat baik, pertahankan.",IF(Q39="Baik","Bagus, sudah baik, dapat lebih ditingkatkan.",IF(Q39="Cukup","Cukup baik, ada baiknya perlu sekali ditingkatkan.",IF(Q39="Kurang","Kurang, sangat perlu perbaikan secara menyeluruh.",""))))) -> Bagus, sudah amat baik, pertahankan. | P39: =(K39/I39)*100 -> 94.736842 | Q39: =IF(P39<=50,("Buruk"),IF(P39<=60,("Kurang"),IF(P39<=75,("Cukup"),IF(P39<=90,("Baik"),("Sangat Baik"))))) -> Sangat Baik | R39: =IF(Q41="Sangat Baik","C",IF(Q41="Baik","J",IF(Q41="Cukup","K",IF(Q41="Kurang","L","")))) -> C
F40: ='SKP JF (KUANTITATIF)'!G35&"" -> Waktu | G40: ='SKP JF (KUANTITATIF)'!H35&"" -> Ketepatan waktu pelaksanaan kegiatan. | I40: ='SKP JF (KUANTITATIF)'!J35 -> 12 | J40: ='SKP JF (KUANTITATIF)'!K35&"" -> Bulan | K40: ='EVALUASI KINERJA KUANTI JF'!K40&"" -> 12 | L40: ='EVALUASI KINERJA KUANTI JF'!L40&"" -> bulan berdasarkan waktu kegiatan | M40: =IF(Q40="Sangat Baik","C",IF(Q40="Baik","J",IF(Q40="Cukup","K",IF(Q40="Kurang","L","")))) -> C | N40: =IF(K40="","",IF(Q40="Sangat Baik","Bagus, sudah amat baik, pertahankan.",IF(Q40="Baik","Bagus, sudah baik, dapat lebih ditingkatkan.",IF(Q40="Cukup","Cukup baik, ada baiknya perlu sekali ditingkatkan.",IF(Q40="Kurang","Kurang, sangat perlu perbaikan secara menyeluruh.",""))))) -> Bagus, sudah amat baik, pertahankan. | P40: =(K40/I40)*100 -> 100 | Q40: =IF(P40<=50,("Buruk"),IF(P40<=60,("Kurang"),IF(P40<=75,("Cukup"),IF(P40<=90,("Baik"),("Sangat Baik"))))) -> Sangat Baik
B41: ='SKP JF (KUANTITATIF)'!B36&"" -> 2 | C41: ='SKP JF (KUANTITATIF)'!C36&"" -> Dokumen kegiatan peningkatan kompetensi dan pengembangan karir ASN di lingkungan Dinas Pendidikan Kab. Lampung Utara | D41: ='SKP JF (KUANTITATIF)'!D36&"" -> Dokumen kegiatan mengikuti Seminar dan atau Webinar Pendidikan di Lingkungan daerah dan Pusat. | F41: ='SKP JF (KUANTITATIF)'!G36&"" -> Kuantitas | G41: ='SKP JF (KUANTITATIF)'!H36&"" -> Jumlah Sertifikat | I41: ='SKP JF (KUANTITATIF)'!J36 -> 1 | J41: ='SKP JF (KUANTITATIF)'!K36&"" -> Sertifikat | K41: ='EVALUASI KINERJA KUANTI JF'!K41&"" -> 1 | L41: ='EVALUASI KINERJA KUANTI JF'!L41&"" -> berdasarkan penilaian pimpinan | M41: =IF(Q41="Sangat Baik","C",IF(Q41="Baik","J",IF(Q41="Cukup","K",IF(Q41="Kurang","L","")))) -> C | N41: =IF(K41="","",IF(Q41="Sangat Baik","Bagus, sudah amat baik, pertahankan.",IF(Q41="Baik","Bagus, sudah baik, dapat lebih ditingkatkan.",IF(Q41="Cukup","Cukup baik, ada baiknya perlu sekali ditingkatkan.",IF(Q41="Kurang","Kurang, sangat perlu perbaikan secara menyeluruh.",""))))) -> Bagus, sudah amat baik, pertahankan. | P41: =(K41/I41)*100 -> 100 | Q41: =IF(P41<=50,("Buruk"),IF(P41<=60,("Kurang"),IF(P41<=75,("Cukup"),IF(P41<=90,("Baik"),("Sangat Baik"))))) -> Sangat Baik
F42: ='SKP JF (KUANTITATIF)'!G37&"" -> Kualitas | G42: ='SKP JF (KUANTITATIF)'!H37&"" -> Sertifikat Webinar APSI Pusat sebagai peserta | I42: ='SKP JF (KUANTITATIF)'!J37 -> 0.95 | J42: ='SKP JF (KUANTITATIF)'!K37&"" -> (Persen) | K42: ='EVALUASI KINERJA KUANTI JF'!K42 -> 0.85 | L42: =IF(K42>=1%,"berdasarkan penilaian pimpinan","") -> berdasarkan penilaian pimpinan | M42: =IF(Q42="Sangat Baik","C",IF(Q42="Baik","J",IF(Q42="Cukup","K",IF(Q42="Kurang","L","")))) -> J | N42: =IF(K42="","",IF(Q42="Sangat Baik","Bagus, sudah amat baik, pertahankan.",IF(Q42="Baik","Bagus, sudah baik, dapat lebih ditingkatkan.",IF(Q42="Cukup","Cukup baik, ada baiknya perlu sekali ditingkatkan.",IF(Q42="Kurang","Kurang, sangat perlu perbaikan secara menyeluruh.",""))))) -> Bagus, sudah baik, dapat lebih ditingkatkan. | P42: =(K42/I42)*100 -> 89.473684 | Q42: =IF(P42<=50,("Buruk"),IF(P42<=60,("Kurang"),IF(P42<=75,("Cukup"),IF(P42<=90,("Baik"),("Sangat Baik"))))) -> Baik | R42: =IF(Q44="Sangat Baik","C",IF(Q44="Baik","J",IF(Q44="Cukup","K",IF(Q44="Kurang","L","")))) -> C
...

Sheet DOK. EVALUASI KINERJA PEGAWAI
F1: HOME
F2: NEXT
B10: DOKUMEN EVALUASI KINERJA PEGAWAI
B12: PERIODE: TRIWULAN I/II/III/IV/TAHUNAN*
B14: ='SKP JF (KUANTITATIF)'!B6&"" -> DINAS PENDIDIKAN KAB. LAMPUNG UTARA | D14: ="PERIODE PENILAIAN: " -> PERIODE PENILAIAN:
D15: ='EVALUASI KINERJA KUANTI JF (2)'!K7&"" -> 01 JANUARI 2022 S.D 31 DESEMBER 2022
B16: 1. | C16: PEGAWAI YANG DINILAI
C17: NAMA | D17: : | E17: ='SKP JF (KUANTITATIF)'!D8&"" -> RUSLAN, S.Pd
C18: NIP | D18: : | E18: ='SKP JF (KUANTITATIF)'!D9&"" -> 19660625 199112 1 001
C19: PANGKAT/GOL. RUANG | D19: : | E19: ='SKP JF (KUANTITATIF)'!D10&"" -> PEMBINA TK.I/ IV.b
C20: JABATAN | D20: : | E20: ='SKP JF (KUANTITATIF)'!D11&"" -> KEPALA SEKOLAH
C21: UNIT KERJA | D21: : | E21: ='SKP JF (KUANTITATIF)'!D12&"" -> UPTD SDN 1 KOTABUMI TENGAH KAB. LAMPUNG UTARA
B22: 2. | C22: PEJABAT PENILAI KINERJA
C23: NAMA | D23: : | E23: ='EVALUASI KINERJA KUANTI JF'!L9&"" -> TUTI ROSPASARI, S.Pd. M.Pd.
C24: NIP | D24: : | E24: ='EVALUASI KINERJA KUANTI JF'!L10&"" -> 19721025 199802 2 003
C25: PANGKAT/GOL. RUANG | D25: : | E25: ='EVALUASI KINERJA KUANTI JF'!L11&"" -> PEMBINA TK.I (IV/b)
C26: JABATAN | D26: : | E26: ='EVALUASI KINERJA KUANTI JF'!L12&"" -> SEKRETARIS DINAS
C27: UNIT KERJA | D27: : | E27: ='EVALUASI KINERJA KUANTI JF'!L13&"" -> DINAS PENDIDIKAN KAB. LAMPUNG UTARA
B28: 3. | C28: ATASAN PEJABAT PENILAI KINERJA
C29: NAMA | D29: : | E29: ='00 DATA'!F20&"" -> SUKATNO, S.H.
C30: NIP | D30: : | E30: ='00 DATA'!F21&"" -> 19721001 199201 1 002
C31: PANGKAT/GOL. RUANG | D31: : | E31: ='00 DATA'!F22&"" -> PEMBINA TK.I (IV/b)
C32: JABATAN | D32: : | E32: ='00 DATA'!F23&"" -> KEPALA DINAS
C33: UNIT KERJA | D33: : | E33: ='00 DATA'!F24&" "&'00 DATA'!D25&" "&'00 DATA'!F25&"" -> DINAS PENDIDIKAN KAB. LAMPUNG UTARA
B34: 4. | C34: EVALUASI KINERJA
C35: CAPAIAN KINERJA ORGANISASI | D35: : | E35: ='EVALUASI KINERJA KUANTI JF'!B15&"" -> BAIK
C36: PREDIKAT KINERJA PEGAWAI | D36: : | E36: ='EVALUASI KINERJA KUANTI JF'!B78&"" -> BAIK
B37: 5. | C37: CATATAN/REKOMENDASI
C42: ='00 DATA'!N8&", "&'00 DATA'!N10&"" -> Kotabumi , 09 Januari 2023 | E42: ='00 DATA'!N8&", "&'00 DATA'!N9&"" -> Kotabumi , 31 Desember 2022
C43: 7. Pegawai yang Dinilai | E43: 6. Pejabat Penilai Kinerja
B47: ="("&E17&")"&"" -> (RUSLAN, S.Pd) | E47: ="("&E23&")"&"" -> (TUTI ROSPASARI, S.Pd. M.Pd.)
B48: ="NIP. "&E18&"" -> NIP. 19660625 199112 1 001 | E48: ="NIP. "&E24&"" -> NIP. 19721025 199802 2 003

Sheet DOK. EVALUASI KINERJA PEGAW (2
F1: HOME
F2: BACK
B10: DOKUMEN EVALUASI KINERJA PEGAWAI
B12: PERIODE: TRIWULAN I/II/III/IV/TAHUNAN*
B14: ='SKP JF (KUANTITATIF)'!B6&"" -> DINAS PENDIDIKAN KAB. LAMPUNG UTARA | D14: ="PERIODE PENILAIAN: " -> PERIODE PENILAIAN:
D15: ='DOK. EVALUASI KINERJA PEGAWAI'!D15:E15&"" -> 01 JANUARI 2022 S.D 31 DESEMBER 2022
B16: 1. | C16: PEGAWAI YANG DINILAI
C17: NAMA | D17: : | E17: ='SKP JF (KUANTITATIF)'!D8&"" -> RUSLAN, S.Pd
C18: NIP | D18: : | E18: ='SKP JF (KUANTITATIF)'!D9&"" -> 19660625 199112 1 001
C19: PANGKAT/GOL. RUANG | D19: : | E19: ='SKP JF (KUANTITATIF)'!D10&"" -> PEMBINA TK.I/ IV.b
C20: JABATAN | D20: : | E20: ='SKP JF (KUANTITATIF)'!D11&"" -> KEPALA SEKOLAH
C21: UNIT KERJA | D21: : | E21: ='SKP JF (KUANTITATIF)'!D12&"" -> UPTD SDN 1 KOTABUMI TENGAH KAB. LAMPUNG UTARA
B22: 2. | C22: PEJABAT PENILAI KINERJA
C23: NAMA | D23: : | E23: ='EVALUASI KINERJA KUANTI JF'!L9&"" -> TUTI ROSPASARI, S.Pd. M.Pd.
C24: NIP | D24: : | E24: ='EVALUASI KINERJA KUANTI JF'!L10&"" -> 19721025 199802 2 003
C25: PANGKAT/GOL. RUANG | D25: : | E25: ='EVALUASI KINERJA KUANTI JF'!L11&"" -> PEMBINA TK.I (IV/b)
C26: JABATAN | D26: : | E26: ='EVALUASI KINERJA KUANTI JF'!L12&"" -> SEKRETARIS DINAS
C27: UNIT KERJA | D27: : | E27: ='EVALUASI KINERJA KUANTI JF'!L13&"" -> DINAS PENDIDIKAN KAB. LAMPUNG UTARA
B28: 3. | C28: ATASAN PEJABAT PENILAI KINERJA
C29: NAMA | D29: : | E29: ='00 DATA'!F20&"" -> SUKATNO, S.H.
C30: NIP | D30: : | E30: ='00 DATA'!F21&"" -> 19721001 199201 1 002
C31: PANGKAT/GOL. RUANG | D31: : | E31: ='00 DATA'!F22&"" -> PEMBINA TK.I (IV/b)
C32: JABATAN | D32: : | E32: ='00 DATA'!F23&"" -> KEPALA DINAS
C33: UNIT KERJA | D33: : | E33: ='00 DATA'!F24&" "&'00 DATA'!D25&" "&'00 DATA'!F25&"" -> DINAS PENDIDIKAN KAB. LAMPUNG UTARA
B34: 4. | C34: EVALUASI KINERJA
C35: CAPAIAN KINERJA ORGANISASI | D35: : | E35: ='EVALUASI KINERJA KUANTI JF'!B15&"" -> BAIK
C36: PREDIKAT KINERJA PEGAWAI | D36: : | E36: ='EVALUASI KINERJA KUANTI JF'!B78&"" -> BAIK
B37: 5. | C37: CATATAN/REKOMENDASI
B39: 6. | C39: KEBERATAN
B41: 7. | C41: PENJELASAN PEJABAT PENILAI KINERJA ATAS KEBERATAN
B43: 8. | C43: KEPUTUSAN DAN REKOMENDASI ATASAN PEJABAT PENILAI KINERJA
C46: ='00 DATA'!N8&", "&'00 DATA'!N10&"" -> Kotabumi , 09 Januari 2023 | E46: ='00 DATA'!N8&", "&'00 DATA'!N9&"" -> Kotabumi , 31 Desember 2022
C47: 10. Pegawai yang Dinilai | E47: 9. Pejabat Penilai Kinerja
B51: ="("&E17&")"&"" -> (RUSLAN, S.Pd) | E51: ="("&E23&")"&"" -> (TUTI ROSPASARI, S.Pd. M.Pd.)
B52: ="NIP. "&E18&"" -> NIP. 19660625 199112 1 001 | E52: ="NIP. "&E24&"" -> NIP. 19721025 199802 2 003
D54: ='00 DATA'!N8&", "&'00 DATA'!N11&"" -> Kotabumi , 09 Januari 2023
D55: 11. Atasan Pejabat Penilai Kinerja
D59: =E29&"" -> SUKATNO, S.H.
D60: ="NIP."&E30&"" -> NIP.19721001 199201 1 002

Sheet EVALUASI KINERJA KUANTI JF
A1: A | O1: HOME
B2: EVALUASI KINERJA PEGAWAI
B3: ='SKP JF (KUANTITATIF)'!B3&"" -> JABATAN FUNGSIONAL KEPALA SEKOLAH
B4: PENDEKATAN HASIL KERJA KUANTITATIF
B6: PERIODE: TRIWULAN I/II/III/IV-AKHIR*
B7: ='SKP JF (KUANTITATIF)'!B6&"" -> DINAS PENDIDIKAN KAB. LAMPUNG UTARA | H7: PERIODE PENILAIAN: | K7: ='SKP JF (KUANTITATIF)'!H6&"" -> 01 JANUARI 2022 S.D 31 DESEMBER 2022
B8: NO. | C8: PEGAWAI YANG DINILAI | H8: NO. | I8: PEJABAT PENILAI KINERJA
B9: 1 | C9: NAMA | E9: ='SKP JF (KUANTITATIF)'!D8&"" -> RUSLAN, S.Pd | H9: 1 | I9: NAMA | L9: =IF(A1="A",'00 DATA'!F12,IF(A1="B",'00 DATA'!N20,"")) -> TUTI ROSPASARI, S.Pd. M.Pd.
B10: 2 | C10: NIP | E10: ='SKP JF (KUANTITATIF)'!D9&"" -> 19660625 199112 1 001 | H10: 2 | I10: NIP | L10: =IF(A1="A",'00 DATA'!F13,IF(A1="B",'00 DATA'!N21,"")) -> 19721025 199802 2 003
B11: 3 | C11: PANGKAT/GOL. RUANG | E11: ='SKP JF (KUANTITATIF)'!D10&"" -> PEMBINA TK.I/ IV.b | H11: 3 | I11: PANGKAT/GOL.RUANG | L11: =IF(A1="A",'00 DATA'!F14,IF(A1="B",'00 DATA'!N22,"")) -> PEMBINA TK.I (IV/b)
B12: 4 | C12: JABATAN | E12: ='SKP JF (KUANTITATIF)'!D11&"" -> KEPALA SEKOLAH | H12: 4 | I12: JABATAN | L12: =IF(A1="A",'00 DATA'!F15,IF(A1="B",'00 DATA'!N23,"")) -> SEKRETARIS DINAS
B13: 5 | C13: UNIT KERJA | E13: ='SKP JF (KUANTITATIF)'!D12&"" -> UPTD SDN 1 KOTABUMI TENGAH KAB. LAMPUNG UTARA | H13: 5 | I13: INSTANSI | L13: =IF(A1="A",'00 DATA'!F16&" "&'00 DATA'!D17&" "&'00 DATA'!F17&"",IF(A1="B",'00 DATA'!N24&" "&'00 DATA'!L25&" "&'00 DATA'!N25,"")) -> DINAS PENDIDIKAN KAB. LAMPUNG UTARA
B14: CAPAIAN KINERJA ORGANISASI*
B15: ='00 DATA'!P6&"" -> BAIK
B16: POLA DISTRIBUSI:
B18: HASIL KERJA
B19: NO. | C19: RENCANA HASIL KERJA PIMPINAN YANG DIINTERVENSI | D19: RENCANA HASIL KERJA | F19: ASPEK | G19: INDIKATOR KINERJA INDIVIDU | J19: TARGET | K19: REALISASI BERDASARKAN BUKTI DUKUNG | M19: UMPAN BALIK BERKELANJUTAN BERDASARKAN BUKTI DUKUNG
B20: (1) | C20: (2) | D20: (3) | F20: (4) | G20: (5) | J20: (6) | K20: (7) | N20: (8)
B21: A. UTAMA | S21: 91-100 | T21: 76-90 | U21: 61-75 | V21: 51-60
B22: ='SKP JF (KUANTITATIF)'!B17&"" -> 1 | C22: ='SKP JF (KUANTITATIF)'!C17&"" -> Meningkatnya aksesibilitas dan kualitas Pendidikan Dasar Dinas Pendidikan Kab. Lampung Utara | D22: ='SKP JF (KUANTITATIF)'!D17&"" -> Dokumen Program Kerja Sekolah dalam bidang Manajerial, Kewirausahaan, Supervisi Guru dan Tendik dalam penyelenggaraan dan atau pengelolaan Sekolah. | F22: ='SKP JF (KUANTITATIF)'!G17&"" -> Kuantitas | G22: ='SKP JF (KUANTITATIF)'!H17&"" -> Jumlah Dokumen Program | I22: ='SKP JF (KUANTITATIF)'!J17&"" -> 2 | J22: ='SKP JF (KUANTITATIF)'!K17&"" -> Dokumen | K22: 2 | L22: =IF(K22>=1,"berdasarkan penilaian pimpinan","") -> berdasarkan penilaian pimpinan | M22: =IF(Q22="Sangat Baik","C",IF(Q22="Baik","J",IF(Q22="Cukup","K",IF(Q22="Kurang","L","")))) -> C | N22: =IF(K22="","",IF(Q22="Sangat Baik","Bagus, sudah amat baik, pertahankan.",IF(Q22="Baik","Bagus, sudah baik, dapat lebih ditingkatkan.",IF(Q22="Cukup","Cukup baik, ada baiknya perlu sekali ditingkatkan.",IF(Q22="Kurang","Kurang, sangat perlu perbaikan secara menyeluruh.",""))))) -> Bagus, sudah amat baik, pertahankan. | P22: =(K22/I22)*100 -> 100 | Q22: =IF(P22<=50,("Buruk"),IF(P22<=60,("Kurang"),IF(P22<=75,("Cukup"),IF(P22<=90,("Baik"),("Sangat Baik"))))) -> Sangat Baik | S22: C | T22: J | U22: K | V22: L
F23: ='SKP JF (KUANTITATIF)'!G18&"" -> Kualitas | G23: ='SKP JF (KUANTITATIF)'!H18&"" -> Program Pengawasan dan Program Bimlat Guru / Kepala Sekolah. | I23: ='SKP JF (KUANTITATIF)'!J18 -> 0.95 | J23: ='SKP JF (KUANTITATIF)'!K18&"" -> (Persen) | K23: 0.9 | L23: =IF(K23>=1%,"berdasarkan penilaian pimpinan","") -> berdasarkan penilaian pimpinan | M23: =IF(Q23="Sangat Baik","C",IF(Q23="Baik","J",IF(Q23="Cukup","K",IF(Q23="Kurang","L","")))) -> C | N23: =IF(K23="","",IF(Q23="Sangat Baik","Bagus, sudah amat baik, pertahankan.",IF(Q23="Baik","Bagus, sudah baik, dapat lebih ditingkatkan.",IF(Q23="Cukup","Cukup baik, ada baiknya perlu sekali ditingkatkan.",IF(Q23="Kurang","Kurang, sangat perlu perbaikan secara menyeluruh.",""))))) -> Bagus, sudah amat baik, pertahankan. | P23: =(K23/I23)*100 -> 94.736842 | Q23: =IF(P23<=50,("Buruk"),IF(P23<=60,("Kurang"),IF(P23<=75,("Cukup"),IF(P23<=90,("Baik"),("Sangat Baik"))))) -> Sangat Baik | S23: Sangat Baik | T23: Baik | U23: Cukup | V23: Kurang
F24: ='SKP JF (KUANTITATIF)'!G19&"" -> Waktu | G24: ='SKP JF (KUANTITATIF)'!H19&"" -> Ketepatan waktu pelaksanaan kegiatan. | I24: ='SKP JF (KUANTITATIF)'!J19 -> 1 | J24: ='SKP JF (KUANTITATIF)'!K19&"" -> Bulan | K24: 1 | L24: =IF(K24>=1,"bulan berdasarkan waktu kegiatan","") -> bulan berdasarkan waktu kegiatan | M24: =IF(Q24="Sangat Baik","C",IF(Q24="Baik","J",IF(Q24="Cukup","K",IF(Q24="Kurang","L","")))) -> C | N24: =IF(K24="","",IF(Q24="Sangat Baik","Bagus, sudah amat baik, pertahankan.",IF(Q24="Baik","Bagus, sudah baik, dapat lebih ditingkatkan.",IF(Q24="Cukup","Cukup baik, ada baiknya perlu sekali ditingkatkan.",IF(Q24="Kurang","Kurang, sangat perlu perbaikan secara menyeluruh.",""))))) -> Bagus, sudah amat baik, pertahankan. | P24: =(K24/I24)*100 -> 100 | Q24: =IF(P24<=50,("Buruk"),IF(P24<=60,("Kurang"),IF(P24<=75,("Cukup"),IF(P24<=90,("Baik"),("Sangat Baik"))))) -> Sangat Baik | T24: Chek | U24: 91 | V24: =IF(U24<=50,("Buruk"),IF(U24<=60,("Kurang"),IF(U24<=75,("Cukup"),IF(U24<=90,("Baik"),("Sangat Baik"))))) -> Sangat Baik
B25: ='SKP JF (KUANTITATIF)'!B20&"" -> 2 | C25: ='SKP JF (KUANTITATIF)'!C20&"" -> Meningkatnya aksesibilitas dan kualitas Pendidikan Dasar Dinas Pendidikan Kab. Lampung Utara | D25: ='SKP JF (KUANTITATIF)'!D20&"" -> Laporan pelaksanaan tugas pokok kepala sekolah (Manajerial, Kewirausahaan, Supervisi Guru dan Tendik) dalam penyelenggaraan dan atau pengelolaan Sekolah. | F25: ='SKP JF (KUANTITATIF)'!G20&"" -> Kuantitas | G25: ='SKP JF (KUANTITATIF)'!H20&"" -> Jumlah Laporan Pengawasan | I25: ='SKP JF (KUANTITATIF)'!J20 -> 1 | J25: ='SKP JF (KUANTITATIF)'!K20&"" -> Laporan | K25: 1 | L25: =IF(K25>=1,"berdasarkan penilaian pimpinan","") -> berdasarkan penilaian pimpinan | M25: =IF(Q25="Sangat Baik","C",IF(Q25="Baik","J",IF(Q25="Cukup","K",IF(Q25="Kurang","L","")))) -> C | N25: =IF(K25="","",IF(Q25="Sangat Baik","Bagus, sudah amat baik, pertahankan.",IF(Q25="Baik","Bagus, sudah baik, dapat lebih ditingkatkan.",IF(Q25="Cukup","Cukup baik, ada baiknya perlu sekali ditingkatkan.",IF(Q25="Kurang","Kurang, sangat perlu perbaikan secara menyeluruh.",""))))) -> Bagus, sudah amat baik, pertahankan. | P25: =(K25/I25)*100 -> 100 | Q25: =IF(P25<=50,("Buruk"),IF(P25<=60,("Kurang"),IF(P25<=75,("Cukup"),IF(P25<=90,("Baik"),("Sangat Baik"))))) -> Sangat Baik
F26: ='SKP JF (KUANTITATIF)'!G21&"" -> Kualitas | G26: ='SKP JF (KUANTITATIF)'!H21&"" -> Materi Pengawasan, instrumen, daftar hadir, suket kegiatan dari KS. | I26: ='SKP JF (KUANTITATIF)'!J21 -> 0.95 | J26: ='SKP JF (KUANTITATIF)'!K21&"" -> (Persen) | K26: 0.9 | L26: =IF(K26>=1%,"berdasarkan penilaian pimpinan","") -> berdasarkan penilaian pimpinan | M26: =IF(Q26="Sangat Baik","C",IF(Q26="Baik","J",IF(Q26="Cukup","K",IF(Q26="Kurang","L","")))) -> C | N26: =IF(K26="","",IF(Q26="Sangat Baik","Bagus, sudah amat baik, pertahankan.",IF(Q26="Baik","Bagus, sudah baik, dapat lebih ditingkatkan.",IF(Q26="Cukup","Cukup baik, ada baiknya perlu sekali ditingkatkan.",IF(Q26="Kurang","Kurang, sangat perlu perbaikan secara menyeluruh.",""))))) -> Bagus, sudah amat baik, pertahankan. | P26: =(K26/I26)*100 -> 94.736842 | Q26: =IF(P26<=50,("Buruk"),IF(P26<=60,("Kurang"),IF(P26<=75,("Cukup"),IF(P26<=90,("Baik"),("Sangat Baik"))))) -> Sangat Baik
F27: ='SKP JF (KUANTITATIF)'!G22&"" -> Waktu | G27: ='SKP JF (KUANTITATIF)'!H22&"" -> Ketepatan waktu pelaksanaan kegiatan. | I27: ='SKP JF (KUANTITATIF)'!J22 -> 12 | J27: ='SKP JF (KUANTITATIF)'!K22&"" -> Bulan | K27: 12 | L27: =IF(K27>=1,"bulan berdasarkan waktu kegiatan","") -> bulan berdasarkan waktu kegiatan | M27: =IF(Q27="Sangat Baik","C",IF(Q27="Baik","J",IF(Q27="Cukup","K",IF(Q27="Kurang","L","")))) -> C | N27: =IF(K27="","",IF(Q27="Sangat Baik","Bagus, sudah amat baik, pertahankan.",IF(Q27="Baik","Bagus, sudah baik, dapat lebih ditingkatkan.",IF(Q27="Cukup","Cukup baik, ada baiknya perlu sekali ditingkatkan.",IF(Q27="Kurang","Kurang, sangat perlu perbaikan secara menyeluruh.",""))))) -> Bagus, sudah amat baik, pertahankan. | P27: =(K27/I27)*100 -> 100 | Q27: =IF(P27<=50,("Buruk"),IF(P27<=60,("Kurang"),IF(P27<=75,("Cukup"),IF(P27<=90,("Baik"),("Sangat Baik"))))) -> Sangat Baik
B28: ='SKP JF (KUANTITATIF)'!B23&"" -> 3 | C28: ='SKP JF (KUANTITATIF)'!C23&"" -> Laporan Pelaksanaan kegiatan Program Peningkatan aksesibilitas dan kualitas pendidikan Dinas Pendidikan Kab. Lampung Utara | D28: ='SKP JF (KUANTITATIF)'!D23&"" -> Laporan Evaluasi dan ketercapaian program kerja pelaksanaan tugas pokok kepala sekolah (Manajerial, Kewirausahaan, Supervisi) dalam bentuk EDS dan atau Analisis Hasil Rapor Pendidikan (PBD). | F28: ='SKP JF (KUANTITATIF)'!G23&"" -> Kuantitas | G28: ='SKP JF (KUANTITATIF)'!H23&"" -> Jumlah Laporan Bimlat Guru dan KS. | I28: ='SKP JF (KUANTITATIF)'!J23 -> 1 | J28: ='SKP JF (KUANTITATIF)'!K23&"" -> Laporan | K28: 1 | L28: =IF(K28>=1,"berdasarkan penilaian pimpinan","") -> berdasarkan penilaian pimpinan | M28: =IF(Q28="Sangat Baik","C",IF(Q28="Baik","J",IF(Q28="Cukup","K",IF(Q28="Kurang","L","")))) -> C | N28: =IF(K28="","",IF(Q28="Sangat Baik","Bagus, sudah amat baik, pertahankan.",IF(Q28="Baik","Bagus, sudah baik, dapat lebih ditingkatkan.",IF(Q28="Cukup","Cukup baik, ada baiknya perlu sekali ditingkatkan.",IF(Q28="Kurang","Kurang, sangat perlu perbaikan secara menyeluruh.",""))))) -> Bagus, sudah amat baik, pertahankan. | P28: =(K28/I28)*100 -> 100 | Q28: =IF(P28<=50,("Buruk"),IF(P28<=60,("Kurang"),IF(P28<=75,("Cukup"),IF(P28<=90,("Baik"),("Sangat Baik"))))) -> Sangat Baik
F29: ='SKP JF (KUANTITATIF)'!G24&"" -> Kualitas | G29: ='SKP JF (KUANTITATIF)'!H24&"" -> Materi Instrumen Pengawasan sekolah, daftar hadir, suket dari KS. | I29: ='SKP JF (KUANTITATIF)'!J24 -> 0.95 | J29: ='SKP JF (KUANTITATIF)'!K24&"" -> (Persen) | K29: 0.9 | L29: =IF(K29>=1%,"berdasarkan penilaian pimpinan","") -> berdasarkan penilaian pimpinan | M29: =IF(Q29="Sangat Baik","C",IF(Q29="Baik","J",IF(Q29="Cukup","K",IF(Q29="Kurang","L","")))) -> C | N29: =IF(K29="","",IF(Q29="Sangat Baik","Bagus, sudah amat baik, pertahankan.",IF(Q29="Baik","Bagus, sudah baik, dapat lebih ditingkatkan.",IF(Q29="Cukup","Cukup baik, ada baiknya perlu sekali ditingkatkan.",IF(Q29="Kurang","Kurang, sangat perlu perbaikan secara menyeluruh.",""))))) -> Bagus, sudah amat baik, pertahankan. | P29: =(K29/I29)*100 -> 94.736842 | Q29: =IF(P29<=50,("Buruk"),IF(P29<=60,("Kurang"),IF(P29<=75,("Cukup"),IF(P29<=90,("Baik"),("Sangat Baik"))))) -> Sangat Baik
F30: ='SKP JF (KUANTITATIF)'!G25&"" -> Waktu | G30: ='SKP JF (KUANTITATIF)'!H25&"" -> Ketepatan waktu pelaksanaan kegiatan. | I30: ='SKP JF (KUANTITATIF)'!J25 -> 6 | J30: ='SKP JF (KUANTITATIF)'!K25&"" -> Bulan | K30: 6 | L30: =IF(K30>=1,"bulan berdasarkan waktu kegiatan","") -> bulan berdasarkan waktu kegiatan | M30: =IF(Q30="Sangat Baik","C",IF(Q30="Baik","J",IF(Q30="Cukup","K",IF(Q30="Kurang","L","")))) -> C | N30: =IF(K30="","",IF(Q30="Sangat Baik","Bagus, sudah amat baik, pertahankan.",IF(Q30="Baik","Bagus, sudah baik, dapat lebih ditingkatkan.",IF(Q30="Cukup","Cukup baik, ada baiknya perlu sekali ditingkatkan.",IF(Q30="Kurang","Kurang, sangat perlu perbaikan secara menyeluruh.",""))))) -> Bagus, sudah amat baik, pertahankan. | P30: =(K30/I30)*100 -> 100 | Q30: =IF(P30<=50,("Buruk"),IF(P30<=60,("Kurang"),IF(P30<=75,("Cukup"),IF(P30<=90,("Baik"),("Sangat Baik"))))) -> Sangat Baik
B31: ='SKP JF (KUANTITATIF)'!B26&"" -> 4 | C31: ='SKP JF (KUANTITATIF)'!C26&"" -> Laporan Evaluasi Hasil Program Peningkatan aksesibilitas dan kualitas sesuai peraturan yang berlaku secara efektif dan efisien. | D31: ='SKP JF (KUANTITATIF)'!D26&"" -> Laporan Pengembangan Keprofesian Berkelanjutan Kepala Sekolah dalam bentuk Diklat fungsional kepala sekolah dan atau Karya Tulis Ilmiah Kepala Sekolah. | F31: ='SKP JF (KUANTITATIF)'!G26&"" -> Kuantitas | G31: ='SKP JF (KUANTITATIF)'!H26&"" -> Jumlah Laporan Evaluasi Pengawasan | I31: ='SKP JF (KUANTITATIF)'!J26 -> 1 | J31: ='SKP JF (KUANTITATIF)'!K26&"" -> Laporan | K31: 1 | L31: =IF(K31>=1,"berdasarkan penilaian pimpinan","") -> berdasarkan penilaian pimpinan | M31: =IF(Q31="Sangat Baik","C",IF(Q31="Baik","J",IF(Q31="Cukup","K",IF(Q31="Kurang","L","")))) -> C | N31: =IF(K31="","",IF(Q31="Sangat Baik","Bagus, sudah amat baik, pertahankan.",IF(Q31="Baik","Bagus, sudah baik, dapat lebih ditingkatkan.",IF(Q31="Cukup","Cukup baik, ada baiknya perlu sekali ditingkatkan.",IF(Q31="Kurang","Kurang, sangat perlu perbaikan secara menyeluruh.",""))))) -> Bagus, sudah amat baik, pertahankan. | P31: =(K31/I31)*100 -> 100 | Q31: =IF(P31<=50,("Buruk"),IF(P31<=60,("Kurang"),IF(P31<=75,("Cukup"),IF(P31<=90,("Baik"),("Sangat Baik"))))) -> Sangat Baik
F32: ='SKP JF (KUANTITATIF)'!G27&"" -> Kualitas | G32: ='SKP JF (KUANTITATIF)'!H27&"" -> Instrumen Evaluasi Pengawasan, dafhad, suket kegiatan dari KS. | I32: ='SKP JF (KUANTITATIF)'!J27 -> 0.95 | J32: ='SKP JF (KUANTITATIF)'!K27&"" -> (Persen) | K32: 0.85 | L32: =IF(K32>=1%,"berdasarkan penilaian pimpinan","") -> berdasarkan penilaian pimpinan | M32: =IF(Q32="Sangat Baik","C",IF(Q32="Baik","J",IF(Q32="Cukup","K",IF(Q32="Kurang","L","")))) -> J | N32: =IF(K32="","",IF(Q32="Sangat Baik","Bagus, sudah amat baik, pertahankan.",IF(Q32="Baik","Bagus, sudah baik, dapat lebih ditingkatkan.",IF(Q32="Cukup","Cukup baik, ada baiknya perlu sekali ditingkatkan.",IF(Q32="Kurang","Kurang, sangat perlu perbaikan secara menyeluruh.",""))))) -> Bagus, sudah baik, dapat lebih ditingkatkan. | P32: =(K32/I32)*100 -> 89.473684 | Q32: =IF(P32<=50,("Buruk"),IF(P32<=60,("Kurang"),IF(P32<=75,("Cukup"),IF(P32<=90,("Baik"),("Sangat Baik"))))) -> Baik
F33: ='SKP JF (KUANTITATIF)'!G28&"" -> Waktu | G33: ='SKP JF (KUANTITATIF)'!H28&"" -> Ketepatan waktu pelaksanaan kegiatan. | I33: ='SKP JF (KUANTITATIF)'!J28 -> 2 | J33: ='SKP JF (KUANTITATIF)'!K28&"" -> Bulan | K33: 2 | L33: =IF(K33>=1,"bulan berdasarkan waktu kegiatan","") -> bulan berdasarkan waktu kegiatan | M33: =IF(Q33="Sangat Baik","C",IF(Q33="Baik","J",IF(Q33="Cukup","K",IF(Q33="Kurang","L","")))) -> C | N33: =IF(K33="","",IF(Q33="Sangat Baik","Bagus, sudah amat baik, pertahankan.",IF(Q33="Baik","Bagus, sudah baik, dapat lebih ditingkatkan.",IF(Q33="Cukup","Cukup baik, ada baiknya perlu sekali ditingkatkan.",IF(Q33="Kurang","Kurang, sangat perlu perbaikan secara menyeluruh.",""))))) -> Bagus, sudah amat baik, pertahankan. | P33: =(K33/I33)*100 -> 100 | Q33: =IF(P33<=50,("Buruk"),IF(P33<=60,("Kurang"),IF(P33<=75,("Cukup"),IF(P33<=90,("Baik"),("Sangat Baik"))))) -> Sangat Baik
B34: ='SKP JF (KUANTITATIF)'!B29&"" -> 5 | C34: ='SKP JF (KUANTITATIF)'!C29&"" -> Dokumen kegiatan peningkatan kompetensi dan pengembangan karir ASN di lingkungan Dinas Pendidikan Kab. Lampung Utara | D34: ='SKP JF (KUANTITATIF)'!D29&"" -> Dokumen kegiatan tugas tambahan sebagai Pengurus atau MKKS/KKKS Kab. Lampung Utara | F34: ='SKP JF (KUANTITATIF)'!G29&"" -> Kuantitas | G34: ='SKP JF (KUANTITATIF)'!H29&"" -> Jumlah Laporan Pengembangan Diri | I34: ='SKP JF (KUANTITATIF)'!J29 -> 1 | J34: ='SKP JF (KUANTITATIF)'!K29&"" -> Laporan | K34: 1 | L34: =IF(K34>=1,"berdasarkan penilaian pimpinan","") -> berdasarkan penilaian pimpinan | M34: =IF(Q34="Sangat Baik","C",IF(Q34="Baik","J",IF(Q34="Cukup","K",IF(Q34="Kurang","L","")))) -> C | N34: =IF(K34="","",IF(Q34="Sangat Baik","Bagus, sudah amat baik, pertahankan.",IF(Q34="Baik","Bagus, sudah baik, dapat lebih ditingkatkan.",IF(Q34="Cukup","Cukup baik, ada baiknya perlu sekali ditingkatkan.",IF(Q34="Kurang","Kurang, sangat perlu perbaikan secara menyeluruh.",""))))) -> Bagus, sudah amat baik, pertahankan. | P34: =(K34/I34)*100 -> 100 | Q34: =IF(P34<=50,("Buruk"),IF(P34<=60,("Kurang"),IF(P34<=75,("Cukup"),IF(P34<=90,("Baik"),("Sangat Baik"))))) -> Sangat Baik
F35: ='SKP JF (KUANTITATIF)'!G30&"" -> Kualitas | G35: ='SKP JF (KUANTITATIF)'!H30&"" -> Laporan PD, daftar hadir, suket kegiatan dari Korwas. | I35: ='SKP JF (KUANTITATIF)'!J30 -> 0.95 | J35: ='SKP JF (KUANTITATIF)'!K30&"" -> (Persen) | K35: 0.9 | L35: =IF(K35>=1%,"berdasarkan penilaian pimpinan","") -> berdasarkan penilaian pimpinan | M35: =IF(Q35="Sangat Baik","C",IF(Q35="Baik","J",IF(Q35="Cukup","K",IF(Q35="Kurang","L","")))) -> C | N35: =IF(K35="","",IF(Q35="Sangat Baik","Bagus, sudah amat baik, pertahankan.",IF(Q35="Baik","Bagus, sudah baik, dapat lebih ditingkatkan.",IF(Q35="Cukup","Cukup baik, ada baiknya perlu sekali ditingkatkan.",IF(Q35="Kurang","Kurang, sangat perlu perbaikan secara menyeluruh.",""))))) -> Bagus, sudah amat baik, pertahankan. | P35: =(K35/I35)*100 -> 94.736842 | Q35: =IF(P35<=50,("Buruk"),IF(P35<=60,("Kurang"),IF(P35<=75,("Cukup"),IF(P35<=90,("Baik"),("Sangat Baik"))))) -> Sangat Baik
F36: ='SKP JF (KUANTITATIF)'!G31&"" -> Waktu | G36: ='SKP JF (KUANTITATIF)'!H31&"" -> Ketepatan waktu pelaksanaan kegiatan. | I36: ='SKP JF (KUANTITATIF)'!J31 -> 3 | J36: ='SKP JF (KUANTITATIF)'!K31&"" -> Bulan | K36: 3 | L36: =IF(K36>=1,"bulan berdasarkan waktu kegiatan","") -> bulan berdasarkan waktu kegiatan | M36: =IF(Q36="Sangat Baik","C",IF(Q36="Baik","J",IF(Q36="Cukup","K",IF(Q36="Kurang","L","")))) -> C | N36: =IF(K36="","",IF(Q36="Sangat Baik","Bagus, sudah amat baik, pertahankan.",IF(Q36="Baik","Bagus, sudah baik, dapat lebih ditingkatkan.",IF(Q36="Cukup","Cukup baik, ada baiknya perlu sekali ditingkatkan.",IF(Q36="Kurang","Kurang, sangat perlu perbaikan secara menyeluruh.",""))))) -> Bagus, sudah amat baik, pertahankan. | P36: =(K36/I36)*100 -> 100 | Q36: =IF(P36<=50,("Buruk"),IF(P36<=60,("Kurang"),IF(P36<=75,("Cukup"),IF(P36<=90,("Baik"),("Sangat Baik"))))) -> Sangat Baik
B37: B. TAMBAHAN
B38: ='SKP JF (KUANTITATIF)'!B33&"" -> 1 | C38: ='SKP JF (KUANTITATIF)'!C33&"" -> Dokumen tugas kedinasan lain yang diberikan pimpinan baik lisan maupun tertulis dilingkungan Dinas Pendidikan Kab. Lampung Utara | D38: ='SKP JF (KUANTITATIF)'!D33&"" -> Dokumen kegiatan tugas tambahan sebagai Anggota / Pengurus MKKS/PGRI Kab. Barito Timur. | F38: ='SKP JF (KUANTITATIF)'!G33&"" -> Kuantitas | G38: ='SKP JF (KUANTITATIF)'!H33&"" -> Jumlah Satuan Kegiatan | I38: ='SKP JF (KUANTITATIF)'!J33 -> 1 | J38: ='SKP JF (KUANTITATIF)'!K33&"" -> Dokumen | K38: 1 | L38: =IF(K38>=1,"berdasarkan penilaian pimpinan","") -> berdasarkan penilaian pimpinan | M38: =IF(Q38="Sangat Baik","C",IF(Q38="Baik","J",IF(Q38="Cukup","K",IF(Q38="Kurang","L","")))) -> C | N38: =IF(K38="","",IF(Q38="Sangat Baik","Bagus, sudah amat baik, pertahankan.",IF(Q38="Baik","Bagus, sudah baik, dapat lebih ditingkatkan.",IF(Q38="Cukup","Cukup baik, ada baiknya perlu sekali ditingkatkan.",IF(Q38="Kurang","Kurang, sangat perlu perbaikan secara menyeluruh.",""))))) -> Bagus, sudah amat baik, pertahankan. | P38: =(K38/I38)*100 -> 100 | Q38: =IF(P38<=50,("Buruk"),IF(P38<=60,("Kurang"),IF(P38<=75,("Cukup"),IF(P38<=90,("Baik"),("Sangat Baik"))))) -> Sangat Baik
F39: ='SKP JF (KUANTITATIF)'!G34&"" -> Kualitas | G39: ='SKP JF (KUANTITATIF)'!H34&"" -> Dokumen Tugas Tambahan sebagai Pengurus APSI | I39: ='SKP JF (KUANTITATIF)'!J34 -> 0.95 | J39: ='SKP JF (KUANTITATIF)'!K34&"" -> (Persen) | K39: 0.9 | L39: =IF(K39>=1%,"berdasarkan penilaian pimpinan","") -> berdasarkan penilaian pimpinan | M39: =IF(Q39="Sangat Baik","C",IF(Q39="Baik","J",IF(Q39="Cukup","K",IF(Q39="Kurang","L","")))) -> C | N39: =IF(K39="","",IF(Q39="Sangat Baik","Bagus, sudah amat baik, pertahankan.",IF(Q39="Baik","Bagus, sudah baik, dapat lebih ditingkatkan.",IF(Q39="Cukup","Cukup baik, ada baiknya perlu sekali ditingkatkan.",IF(Q39="Kurang","Kurang, sangat perlu perbaikan secara menyeluruh.",""))))) -> Bagus, sudah amat baik, pertahankan. | P39: =(K39/I39)*100 -> 94.736842 | Q39: =IF(P39<=50,("Buruk"),IF(P39<=60,("Kurang"),IF(P39<=75,("Cukup"),IF(P39<=90,("Baik"),("Sangat Baik"))))) -> Sangat Baik
F40: ='SKP JF (KUANTITATIF)'!G35&"" -> Waktu | G40: ='SKP JF (KUANTITATIF)'!H35&"" -> Ketepatan waktu pelaksanaan kegiatan. | I40: ='SKP JF (KUANTITATIF)'!J35 -> 12 | J40: ='SKP JF (KUANTITATIF)'!K35&"" -> Bulan | K40: 12 | L40: =IF(K40>=1,"bulan berdasarkan waktu kegiatan","") -> bulan berdasarkan waktu kegiatan | M40: =IF(Q40="Sangat Baik","C",IF(Q40="Baik","J",IF(Q40="Cukup","K",IF(Q40="Kurang","L","")))) -> C | N40: =IF(K40="","",IF(Q40="Sangat Baik","Bagus, sudah amat baik, pertahankan.",IF(Q40="Baik","Bagus, sudah baik, dapat lebih ditingkatkan.",IF(Q40="Cukup","Cukup baik, ada baiknya perlu sekali ditingkatkan.",IF(Q40="Kurang","Kurang, sangat perlu perbaikan secara menyeluruh.",""))))) -> Bagus, sudah amat baik, pertahankan. | P40: =(K40/I40)*100 -> 100 | Q40: =IF(P40<=50,("Buruk"),IF(P40<=60,("Kurang"),IF(P40<=75,("Cukup"),IF(P40<=90,("Baik"),("Sangat Baik"))))) -> Sangat Baik
